Workbook

Sheet System Info
A1: Customer | B1: SN11
A2: Serial Number Info:
A3: Hull Serial Number | B3: 1011
A4: RF Modules:
A5: Boat DL | B5: [Restricted]
A6: Internal Cell Module:
A7: IMEI | B7: [Restricted]
A8: SIM
A9: Iridium SBD:
A10: IMEI | B10: [Restricted]
A11: Dest Port | B11: [Restricted]
A12: Iridium RUDICS:
A13: SIM | B13: [Restricted]
A14: MSISDN Data
A15: Iridium Certus:
A16: IMEI
A17: SIM
A18: Cell Router: Pepwave MAX BR1 Pro
A19: LAN | B19: [Restricted]
A20: User Name | B20: [Restricted]
A21: Password | B21: [Restricted]
A22: DHCP | B22: [Restricted]
A23: SSID | B23: [Restricted]
A24: WiFi Type | B24: WPA/WPA2 Personal
A25: WiFi Security | B25: TKIP / AES: CCMP
A26: WiFi PW | B26: [Restricted]
A27: IMEI | B27: [Restricted]
A28: SIM#1
A29: SIM#2
A30: Computer: OnLogic XXXX
A31: Computer Name | B31: [Restricted]
A32: User Name | B32: [Restricted]
A33: Password | B33: [Restricted]
A34: Camera: Axis F44A
A35: LAN | B35: [Restricted]
A36: User Name | B36: [Restricted]
A37: Password | B37: [Restricted]
A38: Axis Site:
A39: User Name
A40: Password
...

Sheet Power Summary
D1: Power
A2: Base Power | D2: W Typ | E2: W Busy
A3: Base System (Motors Off) | D3: 3.5 | E3: =D3 -> 3.5
A4: Internal Cell Modem | D4: 0.2 | E4: 1
A5: Internal Iridium Modem | D5: 0.5 | E5: 2.5
A6: Internal AIS | D6: 2.5 | E6: 4
A7: GPS | D7: 0.8 | E7: =D7 -> 0.8
A8: Wind | D8: 1.2 | E8: =D8 -> 1.2
A9: Waterspeed | D9: 2 | E9: =D9 -> 2
A10: Motors: Drift | D10: 4 | E10: =D10 -> 4
A11: Total Base | D11: =SUM(D3:D10) -> 14.7 | E11: =SUM(E3:E10) -> 19
A12: Payload Items | B12: V | C12: Supply | D12: W Typ | E12: W Busy
A13: Cell Router | B13: 12-28 | C13: 24 | D13: 4 | E13: 6
A14: Camera System | B14: 8-28 | C14: 24 | D14: 8 | E14: 12
A15: Computer | B15: 12 | C15: 38 | D15: 6 | E15: 30
A16: Other Items | F16: Notes
A17: V200 GPS Antenna | B17: 6-36 | C17: 12 | D17: 3.2 | E17: 6.8
A18: SkyLink 6100 | B18: 10-34 | C18: 24 | D18: 7 | E18: 18
A19: Workhorse ADCP | B19: 20-50 | C19: 38 | D19: 2 | E19: 5
A20: Total Payload | D20: =SUM(D13:D15)+SUM(D17:D19) -> 30.2 | E20: =SUM(E13:E15)+SUM(E17:E19) -> 77.8
A21: Total | D21: =D20+D11 -> 44.9 | E21: =E20+E11 -> 96.8

Sheet Main Enclosure
A1: Power Distribution Board | C1: Power | F1: Cable | G1: A Typ | H1: A Max | I1: AWG | J1: L | K1: R | L1: Loss Typ | M1: Loss Max | N1: Loss Typ | O1: Loss Typ
A2: Output | B2: Description | C2: V | D2: W Typ | E2: W Busy | J2: ft - 1 way | K2: Ohm/kft | L2: V | M2: V | N2: W | O2: %
A3: 12V #1 | B3: V200 GPS Antenna | C3: 12 | D3: 3.2 | E3: 6.8 | F3: 4 x 18AWG Tensility | G3: =D3/C3 -> 0.26666667 | H3: =E3/C3 -> 0.56666667 | I3: 18 | J3: 15 | K3: =_xlfn.XLOOKUP(I3,'Wire Data'!$A$2:$A$22,'Wire Data'!$C$2:$C$22) -> 6.4 | L3: =G3*K3*2*J3/1000 -> 0.0512 | M3: =H3*K3*2*J3/1000 -> 0.1088 | N3: =L3*G3 -> 0.013653333 | O3: =N3/D3 -> 0.0042666667
A4: 12V #2 | C4: 12 | F4: 4 x 18AWG Tensility | I4: 18 | J4: 15
A5: 12V #3 | C5: 12
A6: Total 12V | D6: =SUM(D3:D5) -> 3.2 | E6: =SUM(E3:E5) -> 6.8 | N6: =SUM(N3:N5) -> 0.013653333 | O6: =N6/D6 -> 0.0042666667
A7: 24V #1 | B7: Cell Router | C7: 24 | D7: 4 | E7: 6 | F7: 4 x 18AWG Tensility | G7: =D7/C7 -> 0.16666667 | H7: =E7/C7 -> 0.25 | I7: 18 | J7: 15 | K7: =_xlfn.XLOOKUP(I7,'Wire Data'!$A$2:$A$22,'Wire Data'!$C$2:$C$22) -> 6.4 | L7: =G7*K7*2*J7/1000 -> 0.032 | M7: =H7*K7*2*J7/1000 -> 0.048 | N7: =L7*G7 -> 0.0053333333 | O7: =N7/D7 -> 0.0013333333
A8: 24V #2 | B8: Camera System | C8: 24 | D8: 8 | E8: 12 | F8: 4 x 18AWG Tensility | G8: =D8/C8 -> 0.33333333 | H8: =E8/C8 -> 0.5 | I8: 18 | J8: 15 | K8: =_xlfn.XLOOKUP(I8,'Wire Data'!$A$2:$A$22,'Wire Data'!$C$2:$C$22) -> 6.4 | L8: =G8*K8*2*J8/1000 -> 0.064 | M8: =H8*K8*2*J8/1000 -> 0.096 | N8: =L8*G8 -> 0.021333333 | O8: =N8/D8 -> 0.0026666667
A9: 24V #3 | B9: SkyLink | C9: 24 | D9: 7 | E9: 18 | F9: 2 x 18AWG Tensility | G9: =D9/C9 -> 0.29166667 | H9: =E9/C9 -> 0.75 | I9: 18 | J9: 15 | K9: =_xlfn.XLOOKUP(I9,'Wire Data'!$A$2:$A$22,'Wire Data'!$C$2:$C$22) -> 6.4 | L9: =G9*K9*2*J9/1000 -> 0.056 | M9: =H9*K9*2*J9/1000 -> 0.144 | N9: =L9*G9 -> 0.016333333 | O9: =N9/D9 -> 0.0023333333
A10: Total 24V | D10: =SUM(D7:D9) -> 19 | E10: =SUM(E7:E9) -> 36 | N10: =SUM(N7:N9) -> 0.043 | O10: =N10/D10 -> 0.0022631579
A11: VBat #1 | B11: Module1: Computer | C11: 38 | D11: 6 | E11: 30 | F11: 4 x 18AWG Tensility | G11: =D11/C11 -> 0.15789474 | H11: =E11/C11 -> 0.78947368 | I11: 18 | J11: 15 | K11: =_xlfn.XLOOKUP(I11,'Wire Data'!$A$2:$A$22,'Wire Data'!$C$2:$C$22) -> 6.4 | L11: =G11*K11*2*J11/1000 -> 0.030315789 | M11: =H11*K11*2*J11/1000 -> 0.15157895 | N11: =L11*G11 -> 0.0047867036 | O11: =N11/D11 -> 0.00079778393
A12: VBat #2 | B12: Module2: 24V | C12: 38 | F12: 4 x 18AWG Tensility | I12: 18 | J12: 15
A13: VBat #3 | B13: ADCP | C13: 38 | D13: 4 | E13: 70 | F13: 2 x 18AWG Tensility | G13: =D13/C13 -> 0.10526316 | H13: =E13/C13 -> 1.8421053 | I13: 18 | J13: 15 | K13: =_xlfn.XLOOKUP(I13,'Wire Data'!$A$2:$A$22,'Wire Data'!$C$2:$C$22) -> 6.4 | L13: =G13*K13*2*J13/1000 -> 0.020210526 | M13: =H13*K13*2*J13/1000 -> 0.35368421 | N13: =L13*G13 -> 0.0021274238 | O13: =N13/D13 -> 0.00053185596
A14: Total VBat | D14: =SUM(D11:D13) -> 10 | E14: =SUM(E11:E13) -> 100 | N14: =SUM(N11:N13) -> 0.0069141274 | O14: =N14/D14 -> 0.00069141274
A15: Total | D15: =D14+D10+D6 -> 32.2 | E15: =E14+E10+E6 -> 142.8

Sheet Expansion Board
A1: Sensor Connections | F1: Power Regulators
A2: Sensor Power | C2: Supply | D2: VIn | F2: Power In | H2: Supply
A3: V1 | C3: 12V #1 | D3: =_xlfn.XLOOKUP(C3,'Main Enclosure'!$A$3:$A$13,'Main Enclosure'!$C$3:$C$13) -> 12 | F3: V1 | H3: VBat #1
A4: V2 | C4: 12V #2 | D4: =_xlfn.XLOOKUP(C4,'Main Enclosure'!$A$3:$A$13,'Main Enclosure'!$C$3:$C$13) -> 12 | F4: V2 | H4: VBat #2
A5: V3 | C5: VBat #3 | D5: =_xlfn.XLOOKUP(C5,'Main Enclosure'!$A$3:$A$13,'Main Enclosure'!$C$3:$C$13) -> 38 | F5: V3
A6: V4 | D6: =_xlfn.XLOOKUP(C6,'Main Enclosure'!$A$3:$A$13,'Main Enclosure'!$C$3:$C$13) -> #N/A | F6: Power Out | G6: Load | H6: VOut
A7: Output | B7: Sensor | C7: Jumper | D7: VOut | F7: Out 1 | G7: Computer | H7: 12V
A8: SENS 1 | B8: V200 GPS Antenna | C8: V1 | D8: =_xlfn.XLOOKUP(C8,$A$3:$A$6,$D$3:$D$6) -> 12 | F8: Out 2
A9: SENS 2 | D9: =_xlfn.XLOOKUP(C9,$A$3:$A$6,$D$3:$D$6) -> #N/A | F9: Out 3
A10: SENS 3 | B10: ADCP | C10: V3 | D10: =_xlfn.XLOOKUP(C10,$A$3:$A$6,$D$3:$D$6) -> 38
A11: SENS 4 | D11: =_xlfn.XLOOKUP(C11,$A$3:$A$6,$D$3:$D$6) -> #N/A
A12: SENS 5 | D12: =_xlfn.XLOOKUP(C12,$A$3:$A$6,$D$3:$D$6) -> #N/A

Sheet Wire Data
A1: AWG | B1: mm^2 | C1: R/Kft
A2: 0000 | B2: 120 | C2: 0.049
A3: 000 | B3: 95 | C3: 0.062
A4: 00 | B4: 70 | C4: 0.079
A5: 0 | B5: 55 | C5: 0.1
A6: 1 | B6: 50 | C6: 0.126
A7: 2 | B7: 35 | C7: 0.159
A8: 4 | B8: 25 | C8: 0.253
A9: 6 | B9: 16 | C9: 0.4
A10: 8 | B10: 10 | C10: 0.63
A11: 10 | B11: 6 | C11: 1
A12: 12 | B12: 4 | C12: 1.6
A13: 14 | B13: 2.5 | C13: 2.5
A14: 16 | B14: 1.5 | C14: 4
A15: 18 | B15: 0.75 | C15: 6.4
A16: 20 | B16: 0.5 | C16: 10.1
A17: 22 | B17: 0.34 | C17: 16.1
... A22: 32 | B22: 0.032 | C22: 164.1
